Workbook
Name Validatielijst: par!$A$10:$A$25

Sheet skema
A1: Uge | B1: Dag | C1: Emner | D1: Hold ? | H1: Hold ? | L1: Note
D2: SIEB | E2: MANY | F2: IANB | G2: DE | H2: SIEB | I2: MANY | J2: IANB | K2: DE
B3: Turistguide 1
B4: Spring Boot intro
A5: =+IF(WEEKDAY(B5)=2,(skema!B5-par!$B$5+par!$K$6)/7+1,"") -> 5 | B5: =+par!B4 -> 46048 | C5: Introduktion til semester og Spring Boot | L5: Mads væk denne uge
A6: =+IF(WEEKDAY(B6)=2,(skema!B6-par!$B$5+par!$K$6)/7+1,"") | B6: =+B5+IF(WEEKDAY(B5)=6,3,1) -> 46049 | C6: Spring Boot, Turistguide 1
A7: =+IF(WEEKDAY(B7)=2,(skema!B7-par!$B$5+par!$K$6)/7+1,"") | B7: =+B6+IF(WEEKDAY(B6)=6,3,1) -> 46050 | C7: Check-in/vejledning på Turistguide 1 | L7: Online
A8: =+IF(WEEKDAY(B8)=2,(skema!B8-par!$B$5+par!$K$6)/7+1,"") | B8: =+B7+IF(WEEKDAY(B7)=6,3,1) -> 46051 | C8: ITF: | G8: m
A9: =+IF(WEEKDAY(B9)=2,(skema!B9-par!$B$5+par!$K$6)/7+1,"") | B9: =+B8+IF(WEEKDAY(B8)=6,3,1) -> 46052 | C9: Spring Boot arkitektur + opgaver/konsolidering af Spring Boot
B10: HTML/CSS
A11: =+IF(WEEKDAY(B11)=2,(skema!B11-par!$B$5+par!$K$6)/7+1,"") -> 6 | B11: =+B9+IF(WEEKDAY(B9)=6,3,1) -> 46055 | C11: HTML & CSS
A12: =+IF(WEEKDAY(B12)=2,(skema!B12-par!$B$5+par!$K$6)/7+1,"") | B12: =+B11+IF(WEEKDAY(B11)=6,3,1) -> 46056 | C12: Java Collections, Map | L12: repetition af unittest
A13: =+IF(WEEKDAY(B13)=2,(skema!B13-par!$B$5+par!$K$6)/7+1,"") | B13: =+B12+IF(WEEKDAY(B12)=6,3,1) -> 46057 | C13: Check-in/vejledning på Turistguide 1 | L13: Aflevering af Turistguide 1 kl 17.00
A14: =+IF(WEEKDAY(B14)=2,(skema!B14-par!$B$5+par!$K$6)/7+1,"") | B14: =+B13+IF(WEEKDAY(B13)=6,3,1) -> 46058 | C14: ITF: | G14: m
A15: =+IF(WEEKDAY(B15)=2,(skema!B15-par!$B$5+par!$K$6)/7+1,"") | B15: =+B14+IF(WEEKDAY(B14)=6,3,1) -> 46059 | C15: Feedback Turistguide 1
B16: Turistguide 2
B17: Spring Boot arkitektur, Thymeleaf
A18: =+IF(WEEKDAY(B18)=2,(skema!B18-par!$B$5+par!$K$6)/7+1,"") -> 7 | B18: =+B15+IF(WEEKDAY(B15)=6,3,1) -> 46062 | C18: Introduktion til ThymeLeaf | L18: Model
A19: =+IF(WEEKDAY(B19)=2,(skema!B19-par!$B$5+par!$K$6)/7+1,"") | B19: =+B18+IF(WEEKDAY(B18)=6,3,1) -> 46063 | C19: ThymeLeaf, HTML forms & Thymeleaf, Turistguide 2 | L19: ModelAttribute
A20: =+IF(WEEKDAY(B20)=2,(skema!B20-par!$B$5+par!$K$6)/7+1,"") | B20: =+B19+IF(WEEKDAY(B19)=6,3,1) -> 46064 | C20: Check-in/vejledning på Turistguide 2 | L20: Online
A21: =+IF(WEEKDAY(B21)=2,(skema!B21-par!$B$5+par!$K$6)/7+1,"") | B21: =+B20+IF(WEEKDAY(B20)=6,3,1) -> 46065 | C21: ITF: | G21: m
A22: =+IF(WEEKDAY(B22)=2,(skema!B22-par!$B$5+par!$K$6)/7+1,"") | B22: =+B21+IF(WEEKDAY(B21)=6,3,1) -> 46066 | C22: MockMVC og test af Controller
B23: Git og kodekvalitet
A24: =+IF(WEEKDAY(B24)=2,(skema!B24-par!$B$5+par!$K$6)/7+1,"") -> 8 | B24: =+B22+IF(WEEKDAY(B22)=6,3,1) -> 46069 | C24: Operativsystemer, command shell & Git Bash
A25: =+IF(WEEKDAY(B25)=2,(skema!B25-par!$B$5+par!$K$6)/7+1,"") | B25: =+B24+IF(WEEKDAY(B24)=6,3,1) -> 46070 | C25: Kode review med pull requests
A26: =+IF(WEEKDAY(B26)=2,(skema!B26-par!$B$5+par!$K$6)/7+1,"") | B26: =+B25+IF(WEEKDAY(B25)=6,3,1) -> 46071 | C26: Check-in/vejledning på Turistguide 2 | L26: Online
A27: =+IF(WEEKDAY(B27)=2,(skema!B27-par!$B$5+par!$K$6)/7+1,"") | B27: =+B26+IF(WEEKDAY(B26)=6,3,1) -> 46072 | C27: ITF: | G27: m
A28: =+IF(WEEKDAY(B28)=2,(skema!B28-par!$B$5+par!$K$6)/7+1,"") | B28: =+B27+IF(WEEKDAY(B27)=6,3,1) -> 46073 | C28: Statisk kodeanalyse med tools
B29: DevOps, CI/CD
A30: =+IF(WEEKDAY(B30)=2,(skema!B30-par!$B$5+par!$K$6)/7+1,"") -> 9 | B30: =+B28+IF(WEEKDAY(B28)=6,3,1) -> 46076 | C30: GitHub Actions 1
A31: =+IF(WEEKDAY(B31)=2,(skema!B31-par!$B$5+par!$K$6)/7+1,"") | B31: =+B30+IF(WEEKDAY(B30)=6,3,1) -> 46077 | C31: GitHub Actions 2
A32: =+IF(WEEKDAY(B32)=2,(skema!B32-par!$B$5+par!$K$6)/7+1,"") | B32: =+B31+IF(WEEKDAY(B31)=6,3,1) -> 46078 | C32: Check-in/vejledning på Turistguide 2 | L32: Online Aflevering Turistguide 2
A33: =+IF(WEEKDAY(B33)=2,(skema!B33-par!$B$5+par!$K$6)/7+1,"") | B33: =+B32+IF(WEEKDAY(B32)=6,3,1) -> 46079 | C33: ITF: | G33: m
A34: =+IF(WEEKDAY(B34)=2,(skema!B34-par!$B$5+par!$K$6)/7+1,"") | B34: =+B33+IF(WEEKDAY(B33)=6,3,1) -> 46080 | C34: Feedback og review af Turistguide 2
B35: Turistguide 3
B36: Databaser, SQL, E/R modellering
A37: =+IF(WEEKDAY(B37)=2,(skema!B37-par!$B$5+par!$K$6)/7+1,"") -> 10 | B37: =+B34+IF(WEEKDAY(B34)=6,3,1) -> 46083 | C37: E/R model og relationel model | L37: TO DO!! Hele ugen skal redesignes
A38: =+IF(WEEKDAY(B38)=2,(skema!B38-par!$B$5+par!$K$6)/7+1,"") | B38: =+B37+IF(WEEKDAY(B37)=6,3,1) -> 46084 | C38: Introduktion til SQL og DDL
A39: =+IF(WEEKDAY(B39)=2,(skema!B39-par!$B$5+par!$K$6)/7+1,"") | B39: =+B38+IF(WEEKDAY(B38)=6,3,1) -> 46085 | C39: SQL 2 | L39: Online (SQL opgaver)
A40: =+IF(WEEKDAY(B40)=2,(skema!B40-par!$B$5+par!$K$6)/7+1,"") | B40: =+B39+IF(WEEKDAY(B39)=6,3,1) -> 46086 | C40: ITF: | G40: m
...

Sheet par
A1: parameters | D1: Hold F25A | H1: Hold F25B | I1: determination weeknumber
H2: =+VLOOKUP(WEEKDAY(B5),I3:K9,3) -> 3 | I2: jan 1st | J2: day | K2: conversion
I3: 1 | J3: Sunday | K3: -1
A4: startdate | B4: 46048 | I4: 2 | J4: Monday | K4: 0
B5: 46023 | I5: 3 | J5: Tuesday | K5: 1
I6: 4 | J6: Wednesday | K6: 3
D7: m | I7: 5 | J7: Thursday | K7: 3
I8: 6 | J8: Friday | K8: -3
A9: program | D9: e | I9: 7 | J9: Saturday | K9: -2
I11: =+COUNTIF(skema!D4:K122,"m ")+COUNTIF(skema!D4:K122,"e ") -> 0 | J11: =+IF(I11=0,"",CONCATENATE(I11," cells in columns D to K contain spaces! "))
D12: e | J12: =+IF(I11=0,"","Remove spaces to obtain correct totals. ")
D13: m
D18: e | P18: Tourist Guide 1
D19: m | O19: 6 | P19: Spring Boot intro, HTML/CSS
O20: 7 | P20: Spring Boot arkitektur, Thymeleaf, bash
E21: =+Sheet3!C9 -> 0 | P21: Tourist Guide 2
O22: 8 | P22: Kodekvalitet
O23: 9 | P23: Devops, CI/CD
P24: Tourist Guide 3
D25: e | O25: 10 | P25: Databaser, SQL, E/R modellering
O26: 11 | P26: Jdbc, databaseintegration i Spring Boot, database deployment
O27: 12 | P27: Testbar kode med lav kobling, interfaces, sessions
P28: Miniprojekt
O29: 13 | P29: UX/UI, GitHub Projects
O30: 14 | P30: Transaktioner, error handling
D31: e | O31: 15 | P31: Projektarbejde
P32: EFTERÅRSFERIE
D33: m | O33: 16 | P33: Undervisningsfri
P34: Eksamensprojekt
O35: 17 | P35: Review, markdown, readme og contribute
O36: 18 | P36: Projektarbejde
O37: 19 | P37: Projektarbejde
O38: 20 | P38: Projektarbejde
O39: 21 | P39: Projektarbejde
D40: m | O40: 22 | P40: Projektarbejde
D44: e
D46: m
D48: e
D57: e
D60: m
...

Sheet many
A1: Uge | B1: Dag | C1: Emner | D1: Hold ? | H1: Hold ? | L1: Note
D2: SIEB | E2: MANY | F2: IANB | G2: DE | H2: SIEB | I2: MANY | J2: IANB | K2: DE
B3: Turistguide 1
B4: Spring Boot intro
A5: =+IF(WEEKDAY(B5)=2,(many!B5-par!$B$5+par!$K$6)/7+1,"") -> 5 | B5: =+par!B4 -> 46048 | C5: Introduktion til semester og Spring Boot | L5: Mads væk denne uge
A6: =+IF(WEEKDAY(B6)=2,(many!B6-par!$B$5+par!$K$6)/7+1,"") | B6: =+B5+IF(WEEKDAY(B5)=6,3,1) -> 46049 | C6: Spring Boot, Turistguide 1
A7: =+IF(WEEKDAY(B7)=2,(many!B7-par!$B$5+par!$K$6)/7+1,"") | B7: =+B6+IF(WEEKDAY(B6)=6,3,1) -> 46050 | C7: Check-in/vejledning på Turistguide 1 | L7: Online
A8: =+IF(WEEKDAY(B8)=2,(many!B8-par!$B$5+par!$K$6)/7+1,"") | B8: =+B7+IF(WEEKDAY(B7)=6,3,1) -> 46051 | C8: ITF: | G8: m
A9: =+IF(WEEKDAY(B9)=2,(many!B9-par!$B$5+par!$K$6)/7+1,"") | B9: =+B8+IF(WEEKDAY(B8)=6,3,1) -> 46052 | C9: Spring Boot arkitektur + opgaver/konsolidering af Spring Boot
B10: HTML/CSS
A11: =+IF(WEEKDAY(B11)=2,(many!B11-par!$B$5+par!$K$6)/7+1,"") -> 6 | B11: =+B9+IF(WEEKDAY(B9)=6,3,1) -> 46055 | C11: HTML & CSS | E11: x | I11: x
A12: =+IF(WEEKDAY(B12)=2,(many!B12-par!$B$5+par!$K$6)/7+1,"") | B12: =+B11+IF(WEEKDAY(B11)=6,3,1) -> 46056 | C12: Java Collections, Map | L12: repetition af unittest
A13: =+IF(WEEKDAY(B13)=2,(many!B13-par!$B$5+par!$K$6)/7+1,"") | B13: =+B12+IF(WEEKDAY(B12)=6,3,1) -> 46057 | C13: Check-in/vejledning på Turistguide 1 | I13: x | L13: Aflevering af Turistguide 1 kl 17.00
A14: =+IF(WEEKDAY(B14)=2,(many!B14-par!$B$5+par!$K$6)/7+1,"") | B14: =+B13+IF(WEEKDAY(B13)=6,3,1) -> 46058 | C14: ITF: | G14: m
A15: =+IF(WEEKDAY(B15)=2,(many!B15-par!$B$5+par!$K$6)/7+1,"") | B15: =+B14+IF(WEEKDAY(B14)=6,3,1) -> 46059 | C15: Feedback Turistguide 1
B16: Turistguide 2
B17: Spring Boot arkitektur, Thymeleaf
A18: =+IF(WEEKDAY(B18)=2,(many!B18-par!$B$5+par!$K$6)/7+1,"") -> 7 | B18: =+B15+IF(WEEKDAY(B15)=6,3,1) -> 46062 | C18: Introduktion til ThymeLeaf | L18: Model
A19: =+IF(WEEKDAY(B19)=2,(many!B19-par!$B$5+par!$K$6)/7+1,"") | B19: =+B18+IF(WEEKDAY(B18)=6,3,1) -> 46063 | C19: ThymeLeaf, HTML forms & Thymeleaf, Turistguide 2 | L19: ModelAttribute
A20: =+IF(WEEKDAY(B20)=2,(many!B20-par!$B$5+par!$K$6)/7+1,"") | B20: =+B19+IF(WEEKDAY(B19)=6,3,1) -> 46064 | C20: Check-in/vejledning på Turistguide 2 | I20: x | L20: Online
A21: =+IF(WEEKDAY(B21)=2,(many!B21-par!$B$5+par!$K$6)/7+1,"") | B21: =+B20+IF(WEEKDAY(B20)=6,3,1) -> 46065 | C21: ITF: | G21: m
A22: =+IF(WEEKDAY(B22)=2,(many!B22-par!$B$5+par!$K$6)/7+1,"") | B22: =+B21+IF(WEEKDAY(B21)=6,3,1) -> 46066 | C22: MockMVC og test af Controller
B23: Git og kodekvalitet
A24: =+IF(WEEKDAY(B24)=2,(many!B24-par!$B$5+par!$K$6)/7+1,"") -> 8 | B24: =+B22+IF(WEEKDAY(B22)=6,3,1) -> 46069 | C24: Operativsystemer, command shell & Git Bash | E24: x | I24: x
A25: =+IF(WEEKDAY(B25)=2,(many!B25-par!$B$5+par!$K$6)/7+1,"") | B25: =+B24+IF(WEEKDAY(B24)=6,3,1) -> 46070 | C25: Kode review med pull requests
A26: =+IF(WEEKDAY(B26)=2,(many!B26-par!$B$5+par!$K$6)/7+1,"") | B26: =+B25+IF(WEEKDAY(B25)=6,3,1) -> 46071 | C26: Check-in/vejledning på Turistguide 2 | I26: x | L26: Online
A27: =+IF(WEEKDAY(B27)=2,(many!B27-par!$B$5+par!$K$6)/7+1,"") | B27: =+B26+IF(WEEKDAY(B26)=6,3,1) -> 46072 | C27: ITF: | G27: m
A28: =+IF(WEEKDAY(B28)=2,(many!B28-par!$B$5+par!$K$6)/7+1,"") | B28: =+B27+IF(WEEKDAY(B27)=6,3,1) -> 46073 | C28: Statisk kodeanalyse med tools
B29: DevOps, CI/CD
A30: =+IF(WEEKDAY(B30)=2,(many!B30-par!$B$5+par!$K$6)/7+1,"") -> 9 | B30: =+B28+IF(WEEKDAY(B28)=6,3,1) -> 46076 | C30: GitHub Actions 1 | E30: x | I30: x
A31: =+IF(WEEKDAY(B31)=2,(many!B31-par!$B$5+par!$K$6)/7+1,"") | B31: =+B30+IF(WEEKDAY(B30)=6,3,1) -> 46077 | C31: GitHub Actions 2 | E31: x | I31: x
A32: =+IF(WEEKDAY(B32)=2,(many!B32-par!$B$5+par!$K$6)/7+1,"") | B32: =+B31+IF(WEEKDAY(B31)=6,3,1) -> 46078 | C32: Check-in/vejledning på Turistguide 2 | I32: x | L32: Online Aflevering Turistguide 2
A33: =+IF(WEEKDAY(B33)=2,(many!B33-par!$B$5+par!$K$6)/7+1,"") | B33: =+B32+IF(WEEKDAY(B32)=6,3,1) -> 46079 | C33: ITF: | G33: m
A34: =+IF(WEEKDAY(B34)=2,(many!B34-par!$B$5+par!$K$6)/7+1,"") | B34: =+B33+IF(WEEKDAY(B33)=6,3,1) -> 46080 | C34: Feedback og review af Turistguide 2
B35: Turistguide 3
B36: Databaser, SQL, E/R modellering
A37: =+IF(WEEKDAY(B37)=2,(many!B37-par!$B$5+par!$K$6)/7+1,"") -> 10 | B37: =+B34+IF(WEEKDAY(B34)=6,3,1) -> 46083 | C37: E/R model og relationel model | E37: x | I37: x | L37: TO DO!! Hele ugen skal redesignes
A38: =+IF(WEEKDAY(B38)=2,(many!B38-par!$B$5+par!$K$6)/7+1,"") | B38: =+B37+IF(WEEKDAY(B37)=6,3,1) -> 46084 | C38: Introduktion til SQL og DDL
A39: =+IF(WEEKDAY(B39)=2,(many!B39-par!$B$5+par!$K$6)/7+1,"") | B39: =+B38+IF(WEEKDAY(B38)=6,3,1) -> 46085 | C39: SQL 2 | L39: Online (SQL opgaver)
A40: =+IF(WEEKDAY(B40)=2,(many!B40-par!$B$5+par!$K$6)/7+1,"") | B40: =+B39+IF(WEEKDAY(B39)=6,3,1) -> 46086 | C40: ITF: | G40: m
...

Sheet Sheet3
